Workbook

Sheet Cotización
D1: =UPPER(Empresa!$B$4) -> VELARA TALLER S.A.S.
D2: ="NIT "&Empresa!$B$5 -> NIT [000.000.000-0]
D3: =Empresa!$B$6&" · "&Empresa!$B$7 -> [Dirección] · Barranquilla, Colombia
D4: =Empresa!$B$8&" · "&Empresa!$B$9 -> [+57 300 000 0000] · [correo@dominio.com]
D5: =Empresa!$B$10 -> [sitio web]
A7: COTIZACIÓN | E7: N.º
E8: Fecha de emisión
E9: Válida hasta | F9: =IF(F8="","",F8+15)
E10: Asesor
A12: DATOS DEL CLIENTE | E12: VEHÍCULO O PROYECTO
A13: Nombre / razón social | E13: Marca / modelo / año
A14: NIT / C.C. | E14: Placa o referencia
A15: Teléfono | E15: Material y color
A16: Correo | E16: Asesor comercial
A17: Dirección | E17: Teléfono asesor
A18: Ciudad | E18: Correo asesor
A20: ÍTEM | B20: DESCRIPCIÓN | D20: CANT. | E20: VALOR UNITARIO | F20: VALOR TOTAL
A21: 1 | F21: =IF(OR(D21="",E21=""),"",D21*E21)
A22: 2 | F22: =IF(OR(D22="",E22=""),"",D22*E22)
A23: 3 | F23: =IF(OR(D23="",E23=""),"",D23*E23)
A24: 4 | F24: =IF(OR(D24="",E24=""),"",D24*E24)
A25: 5 | F25: =IF(OR(D25="",E25=""),"",D25*E25)
A26: 6 | F26: =IF(OR(D26="",E26=""),"",D26*E26)
A27: 7 | F27: =IF(OR(D27="",E27=""),"",D27*E27)
A28: 8 | F28: =IF(OR(D28="",E28=""),"",D28*E28)
A29: 9 | F29: =IF(OR(D29="",E29=""),"",D29*E29)
A30: 10 | F30: =IF(OR(D30="",E30=""),"",D30*E30)
E32: Subtotal | F32: =SUM(F21:F30) -> 0
C33: Tarifa de IVA | D33: 0.19 | E33: IVA | F33: =ROUND(F32*D33,0) -> 0
E34: TOTAL | F34: =F32+F33 -> 0
A36: CONDICIONES COMERCIALES
A37: • Los precios incluyen materiales, mano de obra e instalación.
A38: • Tiempo estimado de entrega: ____ días hábiles a partir del anticipo.
A39: • Para iniciar la producción se requiere un anticipo del 50 % del valor total.
A40: • El 50 % restante se cancela contra entrega.
A41: • Esta cotización es válida por 15 días calendario.
A42: • Cualquier cambio en el diseño o los materiales puede modificar el precio.
A44: Gracias por confiar en VELARA. Soluciones a medida para su vehículo, su negocio y sus proyectos.
A46: =Empresa!$B$10&" | "&Empresa!$B$8&" | "&Empresa!$B$7 -> [sitio web] | [+57 300 000 0000] | Barranquilla, Colombia
A48: Cómo usar: diligencie las celdas con fondo crema. Valor total, subtotal, IVA, total y "válida hasta" se calculan solos. La tarifa de IVA está en D33 (19 %, tarifa general en Colombia). Los datos del encabezado se editan en la hoja "Empresa".

Sheet Ejemplo
D1: =UPPER(Empresa!$B$4) -> VELARA TALLER S.A.S.
D2: ="NIT "&Empresa!$B$5 -> NIT [000.000.000-0]
D3: =Empresa!$B$6&" · "&Empresa!$B$7 -> [Dirección] · Barranquilla, Colombia
D4: =Empresa!$B$8&" · "&Empresa!$B$9 -> [+57 300 000 0000] · [correo@dominio.com]
D5: =Empresa!$B$10 -> [sitio web]
A7: COTIZACIÓN | E7: N.º | F7: 000125
E8: Fecha de emisión | F8: 46294
E9: Válida hasta | F9: =IF(F8="","",F8+15) -> 46309
E10: Asesor | F10: Diego Franco (ejemplo)
A12: DATOS DEL CLIENTE | E12: VEHÍCULO O PROYECTO
A13: Nombre / razón social | C13: Carlos Gómez (ejemplo) | E13: Marca / modelo / año | F13: Mazda 3 2019
A14: NIT / C.C. | C14: 1.140.000.000 | E14: Placa o referencia | F14: ABC 123
A15: Teléfono | C15: 300 000 0000 | E15: Material y color | F15: Cuero sintético negro, costura roja
A16: Correo | C16: cliente@ejemplo.com | E16: Asesor comercial | F16: Diego Franco
A17: Dirección | C17: Calle 72 # 45 - 20 | E17: Teléfono asesor | F17: 300 000 0000
A18: Ciudad | C18: Barranquilla | E18: Correo asesor | F18: asesor@ejemplo.com
A20: ÍTEM | B20: DESCRIPCIÓN | D20: CANT. | E20: VALOR UNITARIO | F20: VALOR TOTAL
A21: 1 | B21: Tapizado de asientos delanteros | D21: 2 | E21: 450000 | F21: =IF(OR(D21="",E21=""),"",D21*E21) -> 900000
A22: 2 | B22: Forro de puertas | D22: 4 | E22: 120000 | F22: =IF(OR(D22="",E22=""),"",D22*E22) -> 480000
A23: 3 | B23: Tapizado de timón | D23: 1 | E23: 80000 | F23: =IF(OR(D23="",E23=""),"",D23*E23) -> 80000
A24: 4 | B24: Cielo (techo interior) | D24: 1 | E24: 250000 | F24: =IF(OR(D24="",E24=""),"",D24*E24) -> 250000
A25: 5 | F25: =IF(OR(D25="",E25=""),"",D25*E25)
A26: 6 | F26: =IF(OR(D26="",E26=""),"",D26*E26)
A27: 7 | F27: =IF(OR(D27="",E27=""),"",D27*E27)
A28: 8 | F28: =IF(OR(D28="",E28=""),"",D28*E28)
A29: 9 | F29: =IF(OR(D29="",E29=""),"",D29*E29)
A30: 10 | F30: =IF(OR(D30="",E30=""),"",D30*E30)
E32: Subtotal | F32: =SUM(F21:F30) -> 1710000
C33: Tarifa de IVA | D33: 0.19 | E33: IVA | F33: =ROUND(F32*D33,0) -> 324900
E34: TOTAL | F34: =F32+F33 -> 2034900
A36: CONDICIONES COMERCIALES
A37: • Los precios incluyen materiales, mano de obra e instalación.
A38: • Tiempo estimado de entrega: ____ días hábiles a partir del anticipo.
A39: • Para iniciar la producción se requiere un anticipo del 50 % del valor total.
A40: • El 50 % restante se cancela contra entrega.
A41: • Esta cotización es válida por 15 días calendario.
A42: • Cualquier cambio en el diseño o los materiales puede modificar el precio.
A44: Gracias por confiar en VELARA. Soluciones a medida para su vehículo, su negocio y sus proyectos.
A46: =Empresa!$B$10&" | "&Empresa!$B$8&" | "&Empresa!$B$7 -> [sitio web] | [+57 300 000 0000] | Barranquilla, Colombia
A48: Cómo usar: diligencie las celdas con fondo crema. Valor total, subtotal, IVA, total y "válida hasta" se calculan solos. La tarifa de IVA está en D33 (19 %, tarifa general en Colombia). Los datos del encabezado se editan en la hoja "Empresa".
...

Sheet Empresa
A1: DATOS DE LA EMPRESA
A2: Escriba aquí los datos reales una sola vez: el encabezado de las otras hojas se actualiza solo.
A4: Razón social | B4: VELARA TALLER S.A.S.
A5: NIT | B5: [000.000.000-0]
A6: Dirección | B6: [Dirección]
A7: Ciudad | B7: Barranquilla, Colombia
A8: Teléfono | B8: [+57 300 000 0000]
A9: Correo | B9: [correo@dominio.com]
A10: Sitio web | B10: [sitio web]
A11: Responsabilidad tributaria | B11: [Responsable de IVA]
